{"name": "test_case06", "status": "failed", "statusDetails": {"message": "AssertionError: assert 0", "trace": "self = <test_xfail.TestCase object at 0x00000232C125B448>\n\n    def test_case06(self):\n        print(\"执行失败的用例06........\")\n>       assert 0\nE       assert 0\n\ntest_xfail.py:43: AssertionError"}, "start": 1588051809747, "stop": 1588051809748, "uuid": "c8a1b6dd-b7ff-4e0a-b38b-4dec13126cce", "historyId": "54cd9f771044c6b5e0bf6e5364f89293", "testCaseId": "f5519e374c94a7d895c9ed227bccea84", "fullName": "test_xfail.TestCase#test_case06", "labels": [{"name": "suite", "value": "test_xfail"}, {"name": "subSuite", "value": "TestCase"}, {"name": "host", "value": "PC-BFD8TY2"}, {"name": "thread", "value": "1676-MainThread"}, {"name": "framework", "value": "pytest"}, {"name": "language", "value": "cpython3"}, {"name": "package", "value": "test_xfail"}]}