{"name": "test_case03", "status": "failed", "statusDetails": {"message": "AssertionError: assert 0", "trace": "self = <test_xfail.TestCase object at 0x00000232C12626C8>\n\n    @pytest.mark.xfail(condition=1 > 2, reason=\"预期成功，执行成功\")\n    def test_case03(self):\n        \"\"\"03预期成功，实际执行结果也是成功\"\"\"\n        print(\"执行用例03........\")\n>       assert 0\nE       assert 0\n\ntest_xfail.py:29: AssertionError"}, "description": "03预期成功，实际执行结果也是成功", "start": 1588051809736, "stop": 1588051809736, "uuid": "e060f0be-1981-42c5-b32b-94d19b58f749", "historyId": "f1c3c05295285c376beb66c2504b4084", "testCaseId": "9a0d1b4ad73deb5124bddacbb03b9db2", "fullName": "test_xfail.TestCase#test_case03", "labels": [{"name": "suite", "value": "test_xfail"}, {"name": "subSuite", "value": "TestCase"}, {"name": "host", "value": "PC-BFD8TY2"}, {"name": "thread", "value": "1676-MainThread"}, {"name": "framework", "value": "pytest"}, {"name": "language", "value": "cpython3"}, {"name": "package", "value": "test_xfail"}]}