{"name": "test_case01", "status": "skipped", "statusDetails": {"message": "AssertionError: assert 0", "trace": "self = <test_xfail.TestCase object at 0x00000232C11EA8C8>\n\n    @pytest.mark.xfail(condition=1 < 2, reason=\"预期失败，执行失败\")\n    def test_case01(self):\n        '''01预期失败，执行也是失败'''\n    \n        print('执行用例01......')\n>       assert 0\nE       assert 0\n\ntest_xfail.py:17: AssertionError"}, "description": "01预期失败，执行也是失败", "start": 1588051809730, "stop": 1588051809730, "uuid": "fe122942-7687-4bfa-8e44-47ba1cf4daa8", "historyId": "24724b9a4ddc5c71af105c44664c35e0", "testCaseId": "403c8cc6cb8314da589ca33c9b9e6260", "fullName": "test_xfail.TestCase#test_case01", "labels": [{"name": "suite", "value": "test_xfail"}, {"name": "subSuite", "value": "TestCase"}, {"name": "host", "value": "PC-BFD8TY2"}, {"name": "thread", "value": "1676-MainThread"}, {"name": "framework", "value": "pytest"}, {"name": "language", "value": "cpython3"}, {"name": "package", "value": "test_xfail"}]}