{"name": "test_case04", "status": "failed", "statusDetails": {"message": "AssertionError: assert 0", "trace": "self = <test_xfail.TestCase object at 0x00000232C128A088>\n\n    @pytest.mark.xfail(condition=1 > 2, reason=\"预期成功，执行失败\")\n    def test_case04(self):\n        \"\"\"04预期成功，实际执行结果失败了\"\"\"\n        print(\"执行用例04........\")\n>       assert 0\nE       assert 0\n\ntest_xfail.py:35: AssertionError"}, "description": "04预期成功，实际执行结果失败了", "start": 1588051809740, "stop": 1588051809740, "uuid": "c4f5d220-3f44-4ecd-b915-022d0cb2284e", "historyId": "e5a22be1104489104fcc9f772e232b34", "testCaseId": "b9a8cb194adecc11ccc8918a7ff841e8", "fullName": "test_xfail.TestCase#test_case04", "labels": [{"name": "suite", "value": "test_xfail"}, {"name": "subSuite", "value": "TestCase"}, {"name": "host", "value": "PC-BFD8TY2"}, {"name": "thread", "value": "1676-MainThread"}, {"name": "framework", "value": "pytest"}, {"name": "language", "value": "cpython3"}, {"name": "package", "value": "test_xfail"}]}